Workbook

Sheet BRAND
A1: PRIORITY | B1: BRAND | C1: BRAND_WILDCARD | D1: PRIORITY_VLOOKUP | E1: LENGTH | F1: CATEGORY | G1: BUILD
A2: 1 | B2: EMPTY | D2: 1
A3: 2 | B3: ADRIAEN_BROUWER | C3: ADRIAEN_BROUWER | D3: 9 | E3: =LEN(B3) -> 15 | F3: BEER | G3: 1
A4: 2 | B4: TETE_DE_MORT | C4: TETE_DE_MORT;TE_DE_MORT | D4: 2 | E4: =LEN(B4) -> 12 | G4: 1
A5: 2 | B5: HOEGAARDEN | C5: HOEGAARDE;HOEGAERDE;HOEGAARDEN;HOEGAERDEN;HOEGAARDS;HOEGARDEN;HOEGHAARDEN;HOEGAARD;HOEGHARDEN;HOEGHAARDEN;HOOGARDEN | D5: 2 | E5: =LEN(B5) -> 10 | F5: BEER | G5: 1
A6: 2 | B6: KORENWOLF | C6: KORENWOLF | D6: 5 | E6: =LEN(B6) -> 9 | F6: BEER | G6: 0
A7: 3 | B7: MORELLINO_DI_SCANSANO_LE_PUPILLE | C7: MORELLINO_DI_SCANSANO_LE_PUPILLE | D7: 3 | E7: =LEN(B7) -> 32 | F7: BEER | G7: 1
A8: 3 | B8: CUVEE_PRESTIGE_DOMAIN_SKOURAS | C8: CUVEE_PRESTIGE_DOMAIN_SKOURAS | D8: 3 | E8: =LEN(B8) -> 29 | F8: BEER | G8: 1
A9: 3 | B9: CANNONAU_DI_SARDEGNA_RISERVA | C9: CANNONAU_DI_SARDEGNA_RISERVA | D9: 3 | E9: =LEN(B9) -> 28 | F9: BEER | G9: 1
A10: 3 | B10: LA_CORNE_DU_BOIS_DES_PENDUS | C10: LA_CORNE_DU_BOIS_DES_PENDUS | D10: 3 | E10: =LEN(B10) -> 27 | F10: BEER | G10: 1
A11: 3 | B11: HOPFENTHALER_ALKOHOLFREI | C11: HOPFENTHALER | D11: 3 | E11: =LEN(B11) -> 24 | F11: BEER | G11: 1
A12: 3 | B12: LES_SARDINES_MILLESIMEES | C12: LES_SARDINES_MILLESIMEES | D12: 3 | E12: =LEN(B12) -> 24 | F12: BEER | G12: 1
A13: 3 | B13: CHEVALIER_DES_TEMPLIERS | C13: CHEVALIER_DES_TEMPLIERS | D13: 3 | E13: =LEN(B13) -> 23 | F13: BEER | G13: 1
A14: 3 | B14: DOCHTER_VAN_DE_KORENAAR | C14: DOCHTER | D14: 3 | E14: =LEN(B14) -> 23 | F14: BEER | G14: 1
A15: 3 | B15: KISS_MY_NEIGHBOURS_WIFE | C15: KISS_MY_NEIGHBOURS_WIFE | D15: 3 | E15: =LEN(B15) -> 23 | F15: BEER | G15: 1
A16: 3 | B16: SANCTUS_DOMINICUS_PRIOR | C16: SANCTUS_DOMINICUS_PRIOR | D16: 3 | E16: =LEN(B16) -> 23 | F16: BEER | G16: 1
... A111: 3 | B111: FILIP_DE_STOUT | C111: FILIP_DE_STOUT | D111: 3 | E111: =LEN(B111) -> 14 | F111: BEER | G111: 1
A112: 3 | B112: GRAND_CRU_MONK | C112: GRAND_CRU_MONK | D112: 3 | E112: =LEN(B112) -> 14 | G112: 1
A113: 3 | B113: INSALATA_MISTA | C113: INSALATA_MISTA | D113: 3 | E113: =LEN(B113) -> 14 | F113: BEER | G113: 1
A114: 3 | B114: KRIEK_BELL_VUE | C114: KRIEK_BELL_VUE | D114: 3 | E114: =LEN(B114) -> 14 | F114: BEER | G114: 1
A115: 3 | B115: LA_VERMONTOISE | C115: LA_VERMONTOISE | D115: 3 | E115: =LEN(B115) -> 14 | F115: BEER | G115: 1
A116: 3 | B116: MOEDER_MADONNA | C116: MOEDER_MADONNA | D116: 3 | E116: =LEN(B116) -> 14 | F116: BEER | G116: 1
A117: 3 | B117: MOEDER_OVERSTE | C117: OVERSTE | D117: 3 | E117: =LEN(B117) -> 14 | F117: BEER | G117: 1
A118: 3 | B118: MONSTER_ENERGY | C118: MONSTER | D118: 3 | E118: =LEN(B118) -> 14 | F118: BEER | G118: 1
A119: 3 | B119: NONNETJES_BIER | C119: NONNETJES | D119: 3 | E119: =LEN(B119) -> 14 | F119: BEER | G119: 1
A120: 3 | B120: PEERDEVISSCHER | C120: PEERDEVISSCHER;PEERDEVISSER | D120: 3 | E120: =LEN(B120) -> 14 | F120: BEER | G120: 1
A121: 3 | B121: RED_BY_PEIRSUS | C121: RED_BY_PEIRSUS | D121: 3 | E121: =LEN(B121) -> 14 | F121: SOFT_DRINKS | G121: 1
A122: 3 | B122: SAN_PELLEGRINO | C122: SANPELLEGRINO;PELLEGRINO;PELEGRINO;PELLIGRINO;PELLEGRINO;SAN_PELLEGRINO;S.PELLIGRINO | D122: 3 | E122: =LEN(B122) -> 14 | F122: BEER | G122: 1
A123: 3 | B123: YUGEN_KOMBUCHA | C123: YUGEN | D123: 3 | E123: =LEN(B123) -> 14 | F123: BEER | G123: 1
A124: 3 | B124: ZONNEGEMSE_ZOT | C124: ZONNEGEMSE_ZOT;ZONNEGEMSE | D124: 3 | E124: =LEN(B124) -> 14 | F124: BEER | G124: 1
... A874: 3 | B874: WOESTE | C874: WOESTE | D874: 3 | E874: =LEN(B874) -> 6 | F874: BEER | G874: 1
A875: 3 | B875: WOLF_8 | C875: WOLF_8 | D875: 3 | E875: =LEN(B875) -> 6 | G875: 1
A876: 3 | B876: WOLF_7 | C876: WOLF_7 | D876: 3 | E876: =LEN(B876) -> 6 | F876: BEER | G876: 1
A877: 3 | B877: ZYWIEC | C877: ZYWIEC | D877: 3 | E877: =LEN(B877) -> 6 | F877: BEER | G877: 1
A878: 3 | B878: BARBE | C878: BARBE | D878: 3 | E878: =LEN(B878) -> 5 | F878: BEER | G878: 1
A879: 3 | B879: BRASA | C879: BRASA | D879: 3 | E879: =LEN(B879) -> 5 | F879: BEER | G879: 1
A880: 3 | B880: BRETT | C880: BRETT | D880: 3 | E880: =LEN(B880) -> 5 | F880: BEER | G880: 1
A881: 3 | B881: BRICE | C881: BRICE | D881: 3 | E881: =LEN(B881) -> 5 | F881: BEER | G881: 1
A882: 3 | B882: CESAR | C882: CESAR | D882: 3 | E882: =LEN(B882) -> 5 | F882: BEER | G882: 1
A883: 3 | B883: CH_TI | C883: CH_TI;CHTI | D883: 3 | E883: =LEN(B883) -> 5 | F883: BEER | G883: 1
...

Sheet BRAND_READS

Sheet VARIANT
A1: PRIORITY | B1: VARIANT | C1: VARIANT_WILDCARD | D1: VARIANT_BUILD
A2: 1 | B2: CLEMENTINE | C2: CLEMENTINE;CLEMENTINA;CLEMENTIN | D2: 1
A3: 1 | B3: AGRUMES | C3: AGRUMES;CITRUSVRUCHTEN;AGRUMES;CÃTRICOS;ZITRUSFRÃœCHTE;AGRUM;ARUM;AGRUMES,;AGRUME,;AGRUME;/AGRUM;ARGUMES | D3: 1
A4: 1 | B4: APPLE_CHERRY | C4: APPELKERS;POMME_CERISE;CERISE_POMME | D4: 1
A5: 1 | B5: BITTER_LEMON | C5: BITTER_LEMON;BITTERE_CITROEN;CITRON_AMER;LIMÃ“N_AMARGO;BITTERZITRONE;BITTERLEMON | D5: 1
A6: 1 | B6: BLACKCURRANT | C6: BLACKCURRANT;ZWARTE_BES;CASSIS;GROSELLA_NEGRA;SCHWARZE_JOHANNISBEERE | D6: 1
A7: 1 | B7: BLUEBERRY | C7: BLUEBERRY;BLAUWE_BES;MYRTILLE;ARÃNDANO;BLAUBEERE;BOSBES | D7: 1
A8: 1 | B8: CACTUS | C8: CACTUS;CACTUS;CACTUS;CACTUS;KAKTUS | D8: 1
A9: 1 | B9: CASSIS | C9: CASSIS;GROSELLA_NEGRA;SCHWARZE_JOHANNISBEERE | D9: 1
A10: 1 | B10: CHERRY | C10: CHERRY;KERS;CERISE;CEREZA;KIRSCHE;CHERRY;KRIEK;CERISE;CERISE,;KRIECK | D10: 1
A11: 1 | B11: CRANBERRY | C11: CRANBERRY;VEENBES;CANNEBERGE;ARÃNDANO_ROJO;PREISELBEERE | D11: 1
A12: 1 | B12: DRAGONFRUIT | C12: DRAGONFRUIT;DRAKENFRUIT;FRUIT_DU_DRAGON;FRUTA_DEL_DRAGÃ“N;DRACHENFRUCHT | D12: 1
A13: 1 | B13: ELDERFLOWER | C13: ELDERFLOWER;VLIERBLOESEM;FLEUR_DE_SUREAU;FLOR_DE_SAÃšCO;HOLUNDERBLÃœTE | D13: 1
... A111: 1 | B111: FOREST_BERRIES | C111: BOSVRUCHTEN;BOSBESSEN;FOREST_BERRIES | D111: 1
A112: 1 | B112: LEMONGRASS | C112: LEMONGRASS
B113: CUVEE_CLARRISSE | C113: CUVEE_CLARRISSE | D113: 0
B114: GENERAAL | C114: GENERAAL | D114: 0
B115: LINO | C115: LINO | D115: 0
B116: LITE | C116: CHOUFFE_LITE;FE_LITE;LITE_CH | D116: 0
B117: NANO | C117: NANO | D117: 0
B118: STIMULOO | C118: STIMULOO | D118: 0
B119: 1897 | C119: S_1897 | D119: 0
B120: AVALANCHE | C120: ATRIUM_AVALANCHE | D120: 0
B121: BAOBAB | C121: BAOBAB | D121: 0
B122: BATTELAAR | C122: BATTELAAR | D122: 0
B123: BELLE_D'ETE | C123: BELLE_D'ETE | D123: 0
B124: BOS | C124: KLUIZ_BOS | D124: 0
B125: BRAVA_2022 | C125: ATRIUM_BRAVA_2022 | D125: 0
B126: CELESTE | C126: E_CELESTE | D126: 0
B127: COINTESSENCE | C127: E_COINTESSENCE | D127: 0
B128: COL'_HOPCATION | C128: ATRIUM_COL'_HOPCATION | D128: 0
B129: CUVEE_MEILLEURS_VOEUX | C129: S_CUVEE_MEILLEURS_VOEUX | D129: 0
B130: DRY_HOPPED | C130: DRY_HOPPED | D130: 0
B131: DUBBELBOCK | C131: DUBBELBOCK | D131: 0
... B272: STIMULOO | C272: STIMULOO | D272: 0
B273: 1897 | C273: S_1897 | D273: 0
B274: AVALANCHE | C274: ATRIUM_AVALANCHE | D274: 0
B275: BAOBAB | C275: BAOBAB | D275: 0
B276: BATTELAAR | C276: BATTELAAR | D276: 0
B277: BELLE_D'ETE | C277: BELLE_D'ETE | D277: 0
...

Sheet SUB_VARIANT
A1: PRIORITY | B1: SUB_VARIANT | C1: SUB_VARIANT_WILDCARD
B2: ZERO | C2: SANS_ALCOOL;SPECIAL_EFFECT;SANS.ALCOOL;VRIJWIT;NON_IPA;Alkoholfrei;NON_ALC;GEEN_SUIKER;0_SUIKER;ALCOHOL_ARM;0/0;NANO;NILLIS;EPOS;_0;0.2;0.3;0.4;0,1;0,2;0,3;0.4;0.4%;0.5;0,5;0,4;0,4%;0.0;0.00;0.0%;0,0;0,0%;N.A.;N/A;00;ZERO;ALCOHOLVRIJ;ALCOHOLFREE;NON_ALCOHOLIC;ZONDER_ALCOHOL;ALCOHOLFREE;CERO;VIRGIN;Alcool Free;JUPILER_0;STELLA_0;CARLSBERG_0;LIEFMANS_0;LEFFE_BLOND_0;LEFFE_BROWN_0;ALCOHOL_FREE;zero;zèro;z…ro;cero;suikervrij;sugarfree;no sugar;zonder zuiker;SUGAR_FREE;(NA);PEPSI_MAX;ZERO;CERO;zero;cero
B3: ZERO | C3: zero;zèro;z…ro;cero;suikervrij;sugarfree;no sugar;zonder zuiker;SUGAR_FREE;(NA);PEPSI_MAX;ZERO;CERO
B4: GLUTEN_FREE | C4: GLUTEN_FREE;BIOLOGISCH
B5: HOMEMADE | C5: HOMEMADE;HOME_MADE;HUIS;HUISKE;HUISKEN
B6: FRESH | C6: VERS;FRESH;FRAIS;VERSE;FRAICHE
B7: LIGHT | C7: LIGHT;1KCAL;LAAG_IN_SUIKER
B8: HOT | C8: HOT;WARM;CHAUD;WARME
F12: don't start with mixing the beer type and the third

Sheet TAG_MAPPING
A1: KEY | B1: BRAND | C1: TAG_WILDCARDS | D1: EXTRA_TAG_A | E1: EXTRA_TAG_B | F1: KEY_TAG | G1: ZERO | H1: PRIORITY | I1: BRAND_PRIORITY | J1: LENGTH | K1: CATEGORY | L1: VERIFIED | M1: IN_REGISTRY
A2: 13 | PILSNER | | B2: 13 | C2: PILSNER | F2: PILSNER | H2: 5 | I2: =VLOOKUP(B2,BRAND!B:D,3,FALSE) -> 5.5 | J2: 7 | M2: 1
A3: 13 | EXPORT | | B3: 13 | C3: EXPORT | F3: EXPORT | H3: 5 | I3: =VLOOKUP(B3,BRAND!B:D,3,FALSE) -> 5.5 | J3: 6 | M3: 1
A4: 13 | HOP | | B4: 13 | C4: HOP | F4: HOP | H4: 5 | I4: =VLOOKUP(B4,BRAND!B:D,3,FALSE) -> 15 | M4: 1
A5: 1128 | BRUT_BEER | | B5: 1128 | C5: BRUT_BEER | F5: BRUT_BEER | H5: 5 | I5: =VLOOKUP(B5,BRAND!B:D,3,FALSE) -> 5.5 | J5: 9 | K5: #N/A | M5: 0
A6: 1128 | BRUT_ROSE | | B6: 1128 | C6: BRUT_ROSE | F6: BRUT_ROSE | H6: 5 | I6: =VLOOKUP(B6,BRAND!B:D,3,FALSE) -> 5.5 | J6: 9 | K6: #N/A | M6: 0
A7: 1128 | QUADRUPEL | | B7: 1128 | C7: QUADRUPEL | F7: QUADRUPEL | H7: 5 | I7: =VLOOKUP(B7,BRAND!B:D,3,FALSE) -> 5.5 | J7: 9 | K7: #N/A | M7: 0
A8: 1664 | GOLD | | B8: 1664 | C8: GOLD | F8: GOLD | H8: 4 | I8: =VLOOKUP(B8,BRAND!B:D,3,FALSE) -> 3 | J8: =LEN(F8) -> 4 | K8: BEER | L8: 0 | M8: 1
A9: 1664 | FRENCH_IPA | | B9: 1664 | C9: IPA | F9: FRENCH_IPA | H9: 5 | I9: =VLOOKUP(B9,BRAND!B:D,3,FALSE) -> 3 | J9: =LEN(F9) -> 10 | K9: BEER | L9: 0 | M9: 1
A10: 1664 | MILLESIME | | B10: 1664 | C10: MILLESIME | F10: MILLESIME | H10: 5 | I10: =VLOOKUP(B10,BRAND!B:D,3,FALSE) -> 3 | J10: =LEN(F10) -> 9 | K10: BEER | L10: 0 | M10: 1
A11: 1664 | PRESTIGE | | B11: 1664 | C11: PRESTIGE | F11: PRESTIGE | H11: 5 | I11: =VLOOKUP(B11,BRAND!B:D,3,FALSE) -> 3 | J11: =LEN(F11) -> 8 | K11: BEER | L11: 0 | M11: 1
A12: 1664 | MYRTILLE | | B12: 1664 | C12: MYRTILLE | F12: MYRTILLE | H12: 5 | I12: =VLOOKUP(B12,BRAND!B:D,3,FALSE) -> 3 | J12: =LEN(F12) -> 8 | K12: BEER | L12: 0 | M12: 1
A13: 1664 | PASSION | | B13: 1664 | C13: PASSION | F13: PASSION | H13: 5 | I13: =VLOOKUP(B13,BRAND!B:D,3,FALSE) -> 3 | J13: =LEN(F13) -> 7 | K13: BEER | L13: 0 | M13: 1
A14: 1664 | PANACHE | | B14: 1664 | C14: PANACHE | F14: PANACHE | H14: 5 | I14: =VLOOKUP(B14,BRAND!B:D,3,FALSE) -> 3 | J14: =LEN(F14) -> 7 | K14: BEER | L14: 0 | M14: 1
A15: 1664 | BLONDE | ZERO | B15: 1664 | C15: BLONDE;CORE | F15: BLONDE | G15: ZERO | H15: 5 | I15: =VLOOKUP(B15,BRAND!B:D,3,FALSE) -> 3 | J15: =LEN(F15) -> 6 | K15: BEER | L15: 0 | M15: 1
A16: 1664 | LAGER | | B16: 1664 | C16: LAGER | F16: LAGER | H16: 5 | I16: =VLOOKUP(B16,BRAND!B:D,3,FALSE) -> 3 | J16: =LEN(F16) -> 5 | K16: BEER | L16: 0 | M16: 1
A17: 1664 | BLOND | | B17: 1664 | C17: BLOND | F17: BLOND | H17: 5 | I17: =VLOOKUP(B17,BRAND!B:D,3,FALSE) -> 3 | J17: 5 | K17: #N/A | M17: 0
A18: 1664 | WHITE | | B18: 1664 | C18: WHITE | F18: WHITE | H18: 5 | I18: =VLOOKUP(B18,BRAND!B:D,3,FALSE) -> 3 | J18: 5 | K18: #N/A | M18: 0
A19: 1664 | PECHE | | B19: 1664 | C19: PECHE | F19: PECHE | H19: 5 | I19: =VLOOKUP(B19,BRAND!B:D,3,FALSE) -> 3 | J19: =LEN(F19) -> 5 | K19: BEER | L19: 0 | M19: 1
A20: 1664 | WHITE | ZERO | B20: 1664 | C20: WHITE | F20: WHITE | G20: ZERO | H20: 5 | I20: =VLOOKUP(B20,BRAND!B:D,3,FALSE) -> 3 | J20: =LEN(F20) -> 5 | K20: BEER | L20: 0 | M20: 1
A21: 1664 | LAGER | | B21: 1664 | C21: LAGER | F21: LAGER | H21: 5 | I21: =VLOOKUP(B21,BRAND!B:D,3,FALSE) -> 3 | J21: =LEN(F21) -> 5 | K21: BEER | L21: 0 | M21: 1
A22: 1664 | WHITE | | B22: 1664 | C22: WHITE | F22: WHITE | H22: 5 | I22: =VLOOKUP(B22,BRAND!B:D,3,FALSE) -> 3 | J22: =LEN(F22) -> 5 | K22: BEER | L22: 0 | M22: 1
A23: 1664 | HOPPY | | B23: 1664 | C23: HOPPY | F23: HOPPY | H23: 5 | I23: =VLOOKUP(B23,BRAND!B:D,3,FALSE) -> 3 | J23: =LEN(F23) -> 5 | K23: BEER | L23: 0 | M23: 1
A24: 1664 | ROSE | | B24: 1664 | C24: ROSE | F24: ROSE | H24: 5 | I24: =VLOOKUP(B24,BRAND!B:D,3,FALSE) -> 3 | J24: 4 | K24: #N/A | M24: 0
A25: 1664 | BRUT | | B25: 1664 | C25: BRUT | F25: BRUT | H25: 5 | I25: =VLOOKUP(B25,BRAND!B:D,3,FALSE) -> 3 | J25: =LEN(F25) -> 4 | K25: BEER | L25: 0 | M25: 1
A26: 1664 | CRU | | B26: 1664 | C26: CRU | F26: CRU | H26: 5 | I26: =VLOOKUP(B26,BRAND!B:D,3,FALSE) -> 3 | J26: =LEN(F26) -> 3 | K26: BEER | L26: 0 | M26: 1
A27: 1664 | RED | | B27: 1664 | C27: RED | F27: RED | H27: 5 | I27: =VLOOKUP(B27,BRAND!B:D,3,FALSE) -> 3 | J27: =LEN(F27) -> 3 | K27: BEER | L27: 0 | M27: 1
A28: 1818 | SAISON | | B28: 1818 | C28: SAISON | F28: SAISON | H28: 5 | I28: =VLOOKUP(B28,BRAND!B:D,3,FALSE) -> 5.5 | J28: 6 | M28: 1
A29: 1830 | LIBERTE | | B29: 1830 | C29: LIBERTE | F29: LIBERTE | H29: 5 | I29: =VLOOKUP(B29,BRAND!B:D,3,FALSE) -> 5.5 | J29: 7 | M29: 1
A30: 1830 | BLOND | | B30: 1830 | C30: BLOND;CORE | F30: BLOND | H30: 5 | I30: =VLOOKUP(B30,BRAND!B:D,3,FALSE) -> 5.5 | J30: 5 | M30: 1
A31: 1830 | LOI | | B31: 1830 | C31: LOI | F31: LOI | H31: 5 | I31: =VLOOKUP(B31,BRAND!B:D,3,FALSE) -> 5.5 | J31: 3 | M31: 1
A32: 1830 | ROI | | B32: 1830 | C32: ROI | F32: ROI | H32: 5 | I32: =VLOOKUP(B32,BRAND!B:D,3,FALSE) -> 5.5 | J32: 3 | M32: 1
A33: 1906 | MILNUEVE | | B33: 1906 | C33: MILNUEVE | F33: MILNUEVE | H33: 5 | I33: =VLOOKUP(B33,BRAND!B:D,3,FALSE) -> #N/A | J33: 8 | M33: 1
A34: 1906 | BLACK | | B34: 1907 | C34: BLACK | F34: BLACK | H34: 5 | I34: =VLOOKUP(B34,BRAND!B:D,3,FALSE) -> #N/A | J34: 5 | M34: 1
A35: 1906 | IRISH | | B35: 1908 | C35: IRISH | F35: IRISH | H35: 5 | I35: =VLOOKUP(B35,BRAND!B:D,3,FALSE) -> #N/A | J35: 5 | M35: 1
A36: 1906 | CORE | GLUTEN_FREE | B36: 1909 | C36: CORE | F36: CORE | G36: GLUTEN_FREE | H36: 5 | I36: =VLOOKUP(B36,BRAND!B:D,3,FALSE) -> #N/A | J36: 4 | M36: 1
A37: 1906 | CORE | ZERO | B37: 1910 | C37: CORE | F37: CORE | G37: ZERO | H37: 5 | I37: =VLOOKUP(B37,BRAND!B:D,3,FALSE) -> #N/A | J37: 4 | M37: 1
A38: 1906 | RED | | B38: 1911 | C38: RED | F38: RED | H38: 5 | I38: =VLOOKUP(B38,BRAND!B:D,3,FALSE) -> #N/A | J38: 3 | M38: 1
A39: 7700 | IPA | | B39: 7700 | C39: CORE;IPA | F39: IPA | H39: 5 | I39: =VLOOKUP(B39,BRAND!B:D,3,FALSE) -> 5.5 | J39: 3 | L39: 1 | M39: 1
A40: 8410 | DARK | | B40: 8410 | C40: DARK | F40: DARK | H40: 5 | I40: =VLOOKUP(B40,BRAND!B:D,3,FALSE) -> 5.5 | J40: 4 | M40: 1
...

Sheet CATEGORY
A1: VALIDATION_CATEGORY | B1: CATEGORY | C1: CATEGORY_WILDCARD
A2: REFRESHING | B2: SOFT_DRINKS | C2: REGEX:(?<!_)SODA?(?!_);SOFTDRINKS;FRISDRANKEN;FRISSE_DRANKEN;
A3: REFRESHING | B3: JUICES | C3: SAPPEN;JUICES;SUMOS;SAPJES;FRUITSAPPEN;FRUITJUICES;JUS
A4: EXCLUDED | B4: TEAS | C4: THE;TEA;THEE
A5: EXCLUDED | B5: COFFEES | C5: COFFEE;COFFEES;KOFFIE
A6: REFRESHING | B6: KOMBUCHAS | C6: KOMBUCHA
A7: EXCLUDED | B7: CIDERS | C7: CIDER;
A8: EXCLUDED | B8: WHISKEYS | C8: WHISKEY;WHISKY;WISKEY
A9: EXCLUDED | B9: JENEVERS | C9: JENEVER
A10: REFRESHING | B10: WATERS | C10: WATERS;WATER;EAU;LEAU:DEAU
A11: REFRESHING | B11: MILKSHAKES | C11: MILKSHAKE;MILKSHAKES
A12: REFRESHING | B12: SMOOTHIES | C12: SMOOTHIE;SMOOTHIES
... A47: BEER | B47: BEER | C47: BIEREN;CERVEZAS;REGEX:(?:(?<=_)|^)BEER?(?=(?:_|$));REGEX:(?<!_)BEER?(?!_);REGEX:(?:(?<=_)|^)BIER?(?=(?:_|$));REGEX:(?<!_)BIER?(?!_);BIER;HUISBIEREN;KASTEELBIER;BLOND;BLONDES;BLONDE;BRUNE;BLANCHE;BIERTJES;WITBIER;GEUZE;BIERLIJST;DONKER;AMBER;STOUT;TRIPEL;IPA;FLESBIEREN;FRUITBIER;FLESBIER;SUGGESTIEBIER;SUGGESTIEBIEREN;BIERES;BIÈRES;STREEKBIREN;BIERE;BEER;BEERS;TRAPPIST;TAP;TAPS;DRAFT;VAT;FÛT;KLASSIEKERS OP FLES;STELLA ARTOIS;DE MEESTER (ASSORTIMENT KAN WIJZIGEN);BLÛND VAN 'T FLESKE.;VAN HET VAAT.;ZOOR & ZEUT VAN _X0019_T FLESKE.;ROCHEFORT 10;ORVAL;WESTMALLE DUBBEL;WESTMALLE EXTRA;AU F˚T.;BI»RES

Sheet HUISMERK
F1: 1 | G1: 2 | H1: 3 | I1: 4 | J1: 5 | K1: 6 | L1: 7 | M1: 8 | N1: 9 | O1: 10 | P1: 11 | Q1: 12 | R1: 13 | S1: 1 | T1: 2 | U1: 3 | V1: 4 | W1: 5 | X1: 6 | Y1: 7 | Z1: 8 | AA1: 9 | AB1: 10 | AC1: 11 | AD1: 12 | AE1: 13
A2: AH | B2: _ | C2: JUICE | D2: =A2&B2&C2 -> AH_JUICE | E2: =_xlfn.TEXTJOIN(";",TRUE,F2:R2) -> AH_APPELSAP;AH_VERS_GEPERSTE;AH_TOMATENSAP;AH_ANANASSAP;AH_SINAASAPPELSAP | F2: =IF(S2="","",$A2&$B2&S2) -> AH_APPELSAP | G2: =IF(T2="","",$A2&$B2&T2) -> AH_VERS_GEPERSTE | H2: =IF(U2="","",$A2&$B2&U2) -> AH_TOMATENSAP | I2: =IF(V2="","",$A2&$B2&V2) -> AH_ANANASSAP | J2: =IF(W2="","",$A2&$B2&W2) -> AH_SINAASAPPELSAP | K2: =IF(X2="","",$A2&$B2&X2) | L2: =IF(Y2="","",$A2&$B2&Y2) | M2: =IF(Z2="","",$A2&$B2&Z2) | ... R2: =IF(AE2="","",$A2&$B2&AE2) | S2: APPELSAP | T2: VERS_GEPERSTE | U2: TOMATENSAP | V2: ANANASSAP | W2: SINAASAPPELSAP
A3: AH | B3: _ | C3: COLA | D3: =A3&B3&C3 -> AH_COLA | E3: =_xlfn.TEXTJOIN(";",TRUE,F3:R3) | F3: =IF(S3="","",$A3&$B3&S3) | G3: =IF(T3="","",$A3&$B3&T3) | H3: =IF(U3="","",$A3&$B3&U3) | I3: =IF(V3="","",$A3&$B3&V3) | J3: =IF(W3="","",$A3&$B3&W3) | K3: =IF(X3="","",$A3&$B3&X3) | L3: =IF(Y3="","",$A3&$B3&Y3) | M3: =IF(Z3="","",$A3&$B3&Z3) | ... R3: =IF(AE3="","",$A3&$B3&AE3)
A4: AH | B4: _ | C4: SPORTDRINK | D4: =A4&B4&C4 -> AH_SPORTDRINK | E4: =_xlfn.TEXTJOIN(";",TRUE,F4:R4) | F4: =IF(S4="","",$A4&$B4&S4) | G4: =IF(T4="","",$A4&$B4&T4) | H4: =IF(U4="","",$A4&$B4&U4) | I4: =IF(V4="","",$A4&$B4&V4) | J4: =IF(W4="","",$A4&$B4&W4) | K4: =IF(X4="","",$A4&$B4&X4) | L4: =IF(Y4="","",$A4&$B4&Y4) | M4: =IF(Z4="","",$A4&$B4&Z4) | ... R4: =IF(AE4="","",$A4&$B4&AE4)
A5: AH | B5: _ | C5: JUICE | D5: =A5&B5&C5 -> AH_JUICE | E5: =_xlfn.TEXTJOIN(";",TRUE,F5:R5) | F5: =IF(S5="","",$A5&$B5&S5) | G5: =IF(T5="","",$A5&$B5&T5) | H5: =IF(U5="","",$A5&$B5&U5) | I5: =IF(V5="","",$A5&$B5&V5) | J5: =IF(W5="","",$A5&$B5&W5) | K5: =IF(X5="","",$A5&$B5&X5) | L5: =IF(Y5="","",$A5&$B5&Y5) | M5: =IF(Z5="","",$A5&$B5&Z5) | ... R5: =IF(AE5="","",$A5&$B5&AE5)
A6: AH | B6: _ | C6: SMOOTHIE | D6: =A6&B6&C6 -> AH_SMOOTHIE | E6: =_xlfn.TEXTJOIN(";",TRUE,F6:R6) | F6: =IF(S6="","",$A6&$B6&S6) | G6: =IF(T6="","",$A6&$B6&T6) | H6: =IF(U6="","",$A6&$B6&U6) | I6: =IF(V6="","",$A6&$B6&V6) | J6: =IF(W6="","",$A6&$B6&W6) | K6: =IF(X6="","",$A6&$B6&X6) | L6: =IF(Y6="","",$A6&$B6&Y6) | M6: =IF(Z6="","",$A6&$B6&Z6) | ... R6: =IF(AE6="","",$A6&$B6&AE6)
A7: AH | B7: _ | C7: WATER | D7: =A7&B7&C7 -> AH_WATER | E7: =_xlfn.TEXTJOIN(";",TRUE,F7:R7) | F7: =IF(S7="","",$A7&$B7&S7) | G7: =IF(T7="","",$A7&$B7&T7) | H7: =IF(U7="","",$A7&$B7&U7) | I7: =IF(V7="","",$A7&$B7&V7) | J7: =IF(W7="","",$A7&$B7&W7) | K7: =IF(X7="","",$A7&$B7&X7) | L7: =IF(Y7="","",$A7&$B7&Y7) | M7: =IF(Z7="","",$A7&$B7&Z7) | ... R7: =IF(AE7="","",$A7&$B7&AE7)
A8: AH | B8: _ | C8: LEMONADE | D8: =A8&B8&C8 -> AH_LEMONADE | E8: =_xlfn.TEXTJOIN(";",TRUE,F8:R8) | F8: =IF(S8="","",$A8&$B8&S8) | G8: =IF(T8="","",$A8&$B8&T8) | H8: =IF(U8="","",$A8&$B8&U8) | I8: =IF(V8="","",$A8&$B8&V8) | J8: =IF(W8="","",$A8&$B8&W8) | K8: =IF(X8="","",$A8&$B8&X8) | L8: =IF(Y8="","",$A8&$B8&Y8) | M8: =IF(Z8="","",$A8&$B8&Z8) | ... R8: =IF(AE8="","",$A8&$B8&AE8)
A9: AH | B9: _ | C9: SHOTS | D9: =A9&B9&C9 -> AH_SHOTS | E9: =_xlfn.TEXTJOIN(";",TRUE,F9:R9) | F9: =IF(S9="","",$A9&$B9&S9) | G9: =IF(T9="","",$A9&$B9&T9) | H9: =IF(U9="","",$A9&$B9&U9) | I9: =IF(V9="","",$A9&$B9&V9) | J9: =IF(W9="","",$A9&$B9&W9) | K9: =IF(X9="","",$A9&$B9&X9) | L9: =IF(Y9="","",$A9&$B9&Y9) | M9: =IF(Z9="","",$A9&$B9&Z9) | ... R9: =IF(AE9="","",$A9&$B9&AE9)
A10: AH | B10: _ | C10: GRENADINE | D10: =A10&B10&C10 -> AH_GRENADINE | E10: =_xlfn.TEXTJOIN(";",TRUE,F10:R10) | F10: =IF(S10="","",$A10&$B10&S10) | G10: =IF(T10="","",$A10&$B10&T10) | H10: =IF(U10="","",$A10&$B10&U10) | I10: =IF(V10="","",$A10&$B10&V10) | J10: =IF(W10="","",$A10&$B10&W10) | K10: =IF(X10="","",$A10&$B10&X10) | L10: =IF(Y10="","",$A10&$B10&Y10) | M10: =IF(Z10="","",$A10&$B10&Z10) | ... R10: =IF(AE10="","",$A10&$B10&AE10)
A11: AH | B11: _ | C11: YOGURT | D11: =A11&B11&C11 -> AH_YOGURT | E11: =_xlfn.TEXTJOIN(";",TRUE,F11:R11) | F11: =IF(S11="","",$A11&$B11&S11) | G11: =IF(T11="","",$A11&$B11&T11) | H11: =IF(U11="","",$A11&$B11&U11) | I11: =IF(V11="","",$A11&$B11&V11) | J11: =IF(W11="","",$A11&$B11&W11) | K11: =IF(X11="","",$A11&$B11&X11) | L11: =IF(Y11="","",$A11&$B11&Y11) | M11: =IF(Z11="","",$A11&$B11&Z11) | ... R11: =IF(AE11="","",$A11&$B11&AE11)
A12: AH | B12: _ | C12: GINGER_DRINK | D12: =A12&B12&C12 -> AH_GINGER_DRINK | E12: =_xlfn.TEXTJOIN(";",TRUE,F12:R12) | F12: =IF(S12="","",$A12&$B12&S12) | G12: =IF(T12="","",$A12&$B12&T12) | H12: =IF(U12="","",$A12&$B12&U12) | I12: =IF(V12="","",$A12&$B12&V12) | J12: =IF(W12="","",$A12&$B12&W12) | K12: =IF(X12="","",$A12&$B12&X12) | L12: =IF(Y12="","",$A12&$B12&Y12) | M12: =IF(Z12="","",$A12&$B12&Z12) | ... R12: =IF(AE12="","",$A12&$B12&AE12)
A13: AH | B13: _ | C13: ICE_TEA | D13: =A13&B13&C13 -> AH_ICE_TEA | E13: =_xlfn.TEXTJOIN(";",TRUE,F13:R13) | F13: =IF(S13="","",$A13&$B13&S13) | G13: =IF(T13="","",$A13&$B13&T13) | H13: =IF(U13="","",$A13&$B13&U13) | I13: =IF(V13="","",$A13&$B13&V13) | J13: =IF(W13="","",$A13&$B13&W13) | K13: =IF(X13="","",$A13&$B13&X13) | L13: =IF(Y13="","",$A13&$B13&Y13) | M13: =IF(Z13="","",$A13&$B13&Z13) | ... R13: =IF(AE13="","",$A13&$B13&AE13)
A14: AH | B14: _ | C14: REFRESHING | D14: =A14&B14&C14 -> AH_REFRESHING | E14: =_xlfn.TEXTJOIN(";",TRUE,F14:R14) | F14: =IF(S14="","",$A14&$B14&S14) | G14: =IF(T14="","",$A14&$B14&T14) | H14: =IF(U14="","",$A14&$B14&U14) | I14: =IF(V14="","",$A14&$B14&V14) | J14: =IF(W14="","",$A14&$B14&W14) | K14: =IF(X14="","",$A14&$B14&X14) | L14: =IF(Y14="","",$A14&$B14&Y14) | M14: =IF(Z14="","",$A14&$B14&Z14) | ... R14: =IF(AE14="","",$A14&$B14&AE14)
A15: AH | B15: _ | C15: VITAMIN_DRINK | D15: =A15&B15&C15 -> AH_VITAMIN_DRINK | E15: =_xlfn.TEXTJOIN(";",TRUE,F15:R15) -> AH_VITAMIN_DRINK | F15: =IF(S15="","",$A15&$B15&S15) -> AH_VITAMIN_DRINK | G15: =IF(T15="","",$A15&$B15&T15) | H15: =IF(U15="","",$A15&$B15&U15) | I15: =IF(V15="","",$A15&$B15&V15) | J15: =IF(W15="","",$A15&$B15&W15) | K15: =IF(X15="","",$A15&$B15&X15) | L15: =IF(Y15="","",$A15&$B15&Y15) | M15: =IF(Z15="","",$A15&$B15&Z15) | ... R15: =IF(AE15="","",$A15&$B15&AE15) | S15: VITAMIN_DRINK
A16: AH | B16: _ | C16: ENERGY_DRINK | D16: =A16&B16&C16 -> AH_ENERGY_DRINK | E16: =_xlfn.TEXTJOIN(";",TRUE,F16:R16) | F16: =IF(S16="","",$A16&$B16&S16) | G16: =IF(T16="","",$A16&$B16&T16) | H16: =IF(U16="","",$A16&$B16&U16) | I16: =IF(V16="","",$A16&$B16&V16) | J16: =IF(W16="","",$A16&$B16&W16) | K16: =IF(X16="","",$A16&$B16&X16) | L16: =IF(Y16="","",$A16&$B16&Y16) | M16: =IF(Z16="","",$A16&$B16&Z16) | ... R16: =IF(AE16="","",$A16&$B16&AE16)
A17: AH | B17: _ | C17: MILK_DRINK | D17: =A17&B17&C17 -> AH_MILK_DRINK | E17: =_xlfn.TEXTJOIN(";",TRUE,F17:R17) | F17: =IF(S17="","",$A17&$B17&S17) | G17: =IF(T17="","",$A17&$B17&T17) | H17: =IF(U17="","",$A17&$B17&U17) | I17: =IF(V17="","",$A17&$B17&V17) | J17: =IF(W17="","",$A17&$B17&W17) | K17: =IF(X17="","",$A17&$B17&X17) | L17: =IF(Y17="","",$A17&$B17&Y17) | M17: =IF(Z17="","",$A17&$B17&Z17) | ... R17: =IF(AE17="","",$A17&$B17&AE17)
A18: AH | B18: _ | C18: TONIC | D18: =A18&B18&C18 -> AH_TONIC | E18: =_xlfn.TEXTJOIN(";",TRUE,F18:R18) | F18: =IF(S18="","",$A18&$B18&S18) | G18: =IF(T18="","",$A18&$B18&T18) | H18: =IF(U18="","",$A18&$B18&U18) | I18: =IF(V18="","",$A18&$B18&V18) | J18: =IF(W18="","",$A18&$B18&W18) | K18: =IF(X18="","",$A18&$B18&X18) | L18: =IF(Y18="","",$A18&$B18&Y18) | M18: =IF(Z18="","",$A18&$B18&Z18) | ... R18: =IF(AE18="","",$A18&$B18&AE18)

Sheet Sheet1
A1: KEY | B1: BRAND | C1: TAG_WILDCARDS | D1: KEY_TAG | E1: ZERO | F1: PRIORITY | H1: TAG1 | I1: TAG2 | J1: TAG3 | K1: TAG4 | L1: TAG5 | M1: TAG6 | N1: TAG7
A2: =B2&" | "&D2&" | "&E2 -> BEER_GEN | ALTBIER > STICKE | | B2: BEER_GEN | C2: =_xlfn.TEXTJOIN(";",TRUE,D2,H2:N2) -> ALTBIER > STICKE | D2: ALTBIER > STICKE | F2: 3001 | O2: BEER_GEN | CHERRY |
A3: =B3&" | "&D3&" | "&E3 -> BEER_GEN | ALTBIER > TRADITIONAL | | B3: BEER_GEN | C3: =_xlfn.TEXTJOIN(";",TRUE,D3,H3:N3) -> ALTBIER > TRADITIONAL | D3: ALTBIER > TRADITIONAL | F3: 3002 | O3: BEER_GEN | DUBBEL |
A4: =B4&" | "&D4&" | "&E4 -> BEER_GEN | AUSTRALIAN_SPARKLING_ALE | | B4: BEER_GEN | C4: =_xlfn.TEXTJOIN(";",TRUE,D4,H4:N4) -> AUSTRALIAN_SPARKLING_ALE | D4: AUSTRALIAN_SPARKLING_ALE | F4: 3003 | O4: BEER_GEN | RADLER |
A5: =B5&" | "&D5&" | "&E5 -> BEER_GEN | BARLEYWINE > AMERICAN | | B5: BEER_GEN | C5: =_xlfn.TEXTJOIN(";",TRUE,D5,H5:N5) -> BARLEYWINE > AMERICAN | D5: BARLEYWINE > AMERICAN | F5: 3004 | O5: BEER_GEN | TRIPEL |
A6: =B6&" | "&D6&" | "&E6 -> BEER_GEN | BARLEYWINE > ENGLISH | | B6: BEER_GEN | C6: =_xlfn.TEXTJOIN(";",TRUE,D6,H6:N6) -> BARLEYWINE > ENGLISH | D6: BARLEYWINE > ENGLISH | F6: 3005 | O6: BEER_GEN | AMBER |
A7: =B7&" | "&D7&" | "&E7 -> BEER_GEN | BARLEYWINE > OTHER | | B7: BEER_GEN | C7: =_xlfn.TEXTJOIN(";",TRUE,D7,H7:N7) -> BARLEYWINE > OTHER | D7: BARLEYWINE > OTHER | F7: 3006 | O7: BEER_GEN | BLOND |
A8: =B8&" | "&D8&" | "&E8 -> BEER_GEN | BELGIAN_BLONDE | | B8: BEER_GEN | C8: =_xlfn.TEXTJOIN(";",TRUE,D8,H8:N8) -> BELGIAN_BLONDE | D8: BELGIAN_BLONDE | F8: 3007 | O8: BEER_GEN | GREEN |
A9: =B9&" | "&D9&" | "&E9 -> BEER_GEN | BELGIAN_DUBBEL | | B9: BEER_GEN | C9: =_xlfn.TEXTJOIN(";",TRUE,D9,H9:N9) -> BELGIAN_DUBBEL;DUBBEL | D9: BELGIAN_DUBBEL | F9: 3008 | H9: DUBBEL | O9: BEER_GEN | HONEY |
A10: =B10&" | "&D10&" | "&E10 -> BEER_GEN | BELGIAN_ENKEL_/_PATERSBIER | | B10: BEER_GEN | C10: =_xlfn.TEXTJOIN(";",TRUE,D10,H10:N10) -> BELGIAN_ENKEL_/_PATERSBIER;ENKEL;PATERSBIER | D10: BELGIAN_ENKEL_/_PATERSBIER | F10: 3009 | H10: ENKEL | I10: PATERSBIER | O10: BEER_GEN | LIGHT |
A11: =B11&" | "&D11&" | "&E11 -> BEER_GEN | BELGIAN_QUADRUPEL | | B11: BEER_GEN | C11: =_xlfn.TEXTJOIN(";",TRUE,D11,H11:N11) -> BELGIAN_QUADRUPEL;QUADRUPEL | D11: BELGIAN_QUADRUPEL | F11: 3010 | H11: QUADRUPEL | O11: BEER_GEN | PEACH |
A12: =B12&" | "&D12&" | "&E12 -> BEER_GEN | BELGIAN_STRONG_DARK_ALE | | B12: BEER_GEN | C12: =_xlfn.TEXTJOIN(";",TRUE,D12,H12:N12) -> BELGIAN_STRONG_DARK_ALE | D12: BELGIAN_STRONG_DARK_ALE | F12: 3011 | O12: BEER_GEN | WHEAT |
A13: =B13&" | "&D13&" | "&E13 -> BEER_GEN | BELGIAN_STRONG_GOLDEN_ALE | | B13: BEER_GEN | C13: =_xlfn.TEXTJOIN(";",TRUE,D13,H13:N13) -> BELGIAN_STRONG_GOLDEN_ALE | D13: BELGIAN_STRONG_GOLDEN_ALE | F13: 3012 | O13: BEER_GEN | WHITE |
A14: =B14&" | "&D14&" | "&E14 -> BEER_GEN | BELGIAN_TRIPEL | | B14: BEER_GEN | C14: =_xlfn.TEXTJOIN(";",TRUE,D14,H14:N14) -> BELGIAN_TRIPEL;TRIPEL | D14: BELGIAN_TRIPEL | F14: 3013 | H14: TRIPEL | O14: BEER_GEN | BOCK |
A15: =B15&" | "&D15&" | "&E15 -> BEER_GEN | BIERE_DE_CHAMPAGNE_/_BIERE_BRUT | | B15: BEER_GEN | C15: =_xlfn.TEXTJOIN(";",TRUE,D15,H15:N15) -> BIERE_DE_CHAMPAGNE_/_BIERE_BRUT;BRUT;CHAMPAGNE | D15: BIERE_DE_CHAMPAGNE_/_BIERE_BRUT | F15: 3014 | H15: BRUT | I15: CHAMPAGNE | O15: BEER_GEN | ROSE |
A16: =B16&" | "&D16&" | "&E16 -> BEER_GEN | BITTER > BEST | | B16: BEER_GEN | C16: =_xlfn.TEXTJOIN(";",TRUE,D16,H16:N16) -> BITTER > BEST | D16: BITTER > BEST | F16: 3015 | O16: BEER_GEN | RUBY |
A17: =B17&" | "&D17&" | "&E17 -> BEER_GEN | BITTER > EXTRA_SPECIAL_/_STRONG_(ESB) | | B17: BEER_GEN | C17: =_xlfn.TEXTJOIN(";",TRUE,D17,H17:N17) -> BITTER > EXTRA_SPECIAL_/_STRONG_(ESB) | D17: BITTER > EXTRA_SPECIAL_/_STRONG_(ESB) | F17: 3016 | O17: BEER_GEN | WILD |
A18: =B18&" | "&D18&" | "&E18 -> BEER_GEN | BITTER > SESSION_/_ORDINARY | | B18: BEER_GEN | C18: =_xlfn.TEXTJOIN(";",TRUE,D18,H18:N18) -> BITTER > SESSION_/_ORDINARY | D18: BITTER > SESSION_/_ORDINARY | F18: 3017 | O18: BEER_GEN | IPA |
A19: =B19&" | "&D19&" | "&E19 -> BEER_GEN | BLACK_&_TAN | | B19: BEER_GEN | C19: =_xlfn.TEXTJOIN(";",TRUE,D19,H19:N19) -> BLACK_&_TAN | D19: BLACK_&_TAN | F19: 3018 | O19: BEER_GEN | RED |
A20: =B20&" | "&D20&" | "&E20 -> BEER_GEN | BLONDE_/_GOLDEN_ALE > AMERICAN | | B20: BEER_GEN | C20: =_xlfn.TEXTJOIN(";",TRUE,D20,H20:N20) -> BLONDE_/_GOLDEN_ALE > AMERICAN | D20: BLONDE_/_GOLDEN_ALE > AMERICAN | F20: 3019 | O20: BEER_GEN | CORE | ZERO
A21: =B21&" | "&D21&" | "&E21 -> BEER_GEN | BLONDE_/_GOLDEN_ALE > ENGLISH | | B21: BEER_GEN | C21: =_xlfn.TEXTJOIN(";",TRUE,D21,H21:N21) -> BLONDE_/_GOLDEN_ALE > ENGLISH | D21: BLONDE_/_GOLDEN_ALE > ENGLISH | F21: 3020 | O21: BEER_GEN | CORE |
A22: =B22&" | "&D22&" | "&E22 -> BEER_GEN | BLONDE_/_GOLDEN_ALE > OTHER | | B22: BEER_GEN | C22: =_xlfn.TEXTJOIN(";",TRUE,D22,H22:N22) -> BLONDE_/_GOLDEN_ALE > OTHER;BLOND | D22: BLONDE_/_GOLDEN_ALE > OTHER | F22: 3021 | H22: BLOND
A23: =B23&" | "&D23&" | "&E23 -> BEER_GEN | BOCK > DOPPELBOCK | | B23: BEER_GEN | C23: =_xlfn.TEXTJOIN(";",TRUE,D23,H23:N23) -> BOCK > DOPPELBOCK;DOPPELBOCK | D23: BOCK > DOPPELBOCK | F23: 3022 | H23: DOPPELBOCK
A24: =B24&" | "&D24&" | "&E24 -> BEER_GEN | BOCK > EISBOCK | | B24: BEER_GEN | C24: =_xlfn.TEXTJOIN(";",TRUE,D24,H24:N24) -> BOCK > EISBOCK;EISBOCK | D24: BOCK > EISBOCK | F24: 3023 | H24: EISBOCK
A25: =B25&" | "&D25&" | "&E25 -> BEER_GEN | BOCK > HELL_/_MAIBOCK_/_LENTEBOCK | | B25: BEER_GEN | C25: =_xlfn.TEXTJOIN(";",TRUE,D25,H25:N25) -> BOCK > HELL_/_MAIBOCK_/_LENTEBOCK;HELL;MAIBOCK;LENTEBOCK | D25: BOCK > HELL_/_MAIBOCK_/_LENTEBOCK | F25: 3024 | H25: HELL | I25: MAIBOCK | J25: LENTEBOCK
A26: =B26&" | "&D26&" | "&E26 -> BEER_GEN | BOCK > SINGLE_/_TRADITIONAL | | B26: BEER_GEN | C26: =_xlfn.TEXTJOIN(";",TRUE,D26,H26:N26) -> BOCK > SINGLE_/_TRADITIONAL;BOCK | D26: BOCK > SINGLE_/_TRADITIONAL | F26: 3025 | H26: BOCK
A27: =B27&" | "&D27&" | "&E27 -> BEER_GEN | BOCK > WEIZENBOCK | | B27: BEER_GEN | C27: =_xlfn.TEXTJOIN(";",TRUE,D27,H27:N27) -> BOCK > WEIZENBOCK;WEIZENBOCK | D27: BOCK > WEIZENBOCK | F27: 3026 | H27: WEIZENBOCK
A28: =B28&" | "&D28&" | "&E28 -> BEER_GEN | BOCK > WEIZENDOPPELBOCK | | B28: BEER_GEN | C28: =_xlfn.TEXTJOIN(";",TRUE,D28,H28:N28) -> BOCK > WEIZENDOPPELBOCK;WEIZENDOPPELBOCK | D28: BOCK > WEIZENDOPPELBOCK | F28: 3027 | H28: WEIZENDOPPELBOCK
A29: =B29&" | "&D29&" | "&E29 -> BEER_GEN | BRETT_BEER | | B29: BEER_GEN | C29: =_xlfn.TEXTJOIN(";",TRUE,D29,H29:N29) -> BRETT_BEER;BRETT | D29: BRETT_BEER | F29: 3028 | H29: BRETT
A30: =B30&" | "&D30&" | "&E30 -> BEER_GEN | BROWN_ALE > AMERICAN | | B30: BEER_GEN | C30: =_xlfn.TEXTJOIN(";",TRUE,D30,H30:N30) -> BROWN_ALE > AMERICAN | D30: BROWN_ALE > AMERICAN | F30: 3029
A31: =B31&" | "&D31&" | "&E31 -> BEER_GEN | BROWN_ALE > BELGIAN | | B31: BEER_GEN | C31: =_xlfn.TEXTJOIN(";",TRUE,D31,H31:N31) -> BROWN_ALE > BELGIAN | D31: BROWN_ALE > BELGIAN | F31: 3030
A32: =B32&" | "&D32&" | "&E32 -> BEER_GEN | BROWN_ALE > ENGLISH | | B32: BEER_GEN | C32: =_xlfn.TEXTJOIN(";",TRUE,D32,H32:N32) -> BROWN_ALE > ENGLISH | D32: BROWN_ALE > ENGLISH | F32: 3031
A33: =B33&" | "&D33&" | "&E33 -> BEER_GEN | BROWN_ALE > IMPERIAL_/_DOUBLE | | B33: BEER_GEN | C33: =_xlfn.TEXTJOIN(";",TRUE,D33,H33:N33) -> BROWN_ALE > IMPERIAL_/_DOUBLE | D33: BROWN_ALE > IMPERIAL_/_DOUBLE | F33: 3032
A34: =B34&" | "&D34&" | "&E34 -> BEER_GEN | BROWN_ALE > OTHER | | B34: BEER_GEN | C34: =_xlfn.TEXTJOIN(";",TRUE,D34,H34:N34) -> BROWN_ALE > OTHER;BROWN | D34: BROWN_ALE > OTHER | F34: 3033 | H34: BROWN
A35: =B35&" | "&D35&" | "&E35 -> BEER_GEN | CALIFORNIA_COMMON | | B35: BEER_GEN | C35: =_xlfn.TEXTJOIN(";",TRUE,D35,H35:N35) -> CALIFORNIA_COMMON | D35: CALIFORNIA_COMMON | F35: 3034
A36: =B36&" | "&D36&" | "&E36 -> BEER_GEN | CHILLI_/_CHILE_BEER | | B36: BEER_GEN | C36: =_xlfn.TEXTJOIN(";",TRUE,D36,H36:N36) -> CHILLI_/_CHILE_BEER | D36: CHILLI_/_CHILE_BEER | F36: 3035
A37: =B37&" | "&D37&" | "&E37 -> BEER_GEN | CIDER > APPLEWINE | | B37: BEER_GEN | C37: =_xlfn.TEXTJOIN(";",TRUE,D37,H37:N37) -> CIDER > APPLEWINE | D37: CIDER > APPLEWINE | F37: 3036
A38: =B38&" | "&D38&" | "&E38 -> BEER_GEN | CIDER > BASQUE | | B38: BEER_GEN | C38: =_xlfn.TEXTJOIN(";",TRUE,D38,H38:N38) -> CIDER > BASQUE | D38: CIDER > BASQUE | F38: 3037
A39: =B39&" | "&D39&" | "&E39 -> BEER_GEN | CIDER > DRY | | B39: BEER_GEN | C39: =_xlfn.TEXTJOIN(";",TRUE,D39,H39:N39) -> CIDER > DRY | D39: CIDER > DRY | F39: 3038
A40: =B40&" | "&D40&" | "&E40 -> BEER_GEN | CIDER > GRAFF | | B40: BEER_GEN | C40: =_xlfn.TEXTJOIN(";",TRUE,D40,H40:N40) -> CIDER > GRAFF | D40: CIDER > GRAFF | F40: 3039
...

Sheet Sheet2
A1: =_xlfn.TEXTJOIN(";",TRUE,C1:K1) -> BRUISEND;TONIC;WATERS;WATER;SUMOS | B1: CATEGORY | C1: BRUISEND | D1: TONIC | E1: WATERS | F1: WATER | J1: SUMOS
A2: =_xlfn.TEXTJOIN(";",TRUE,C2:K2) -> BIEREN;CERVEZAS | B2: BEER | C2: BIEREN | D2: CERVEZAS
B3: SOFT_DRINKS
B4: WINE
B5: HOT_DRINKS
B6: COCKTAILS | H6: BRUISEND;TONIC;WATERS;WATER;SUMOS
B7: STRONG_DRINKS | H7: BIEREN;CERVEZAS
B8: FOOD
B9: APERITIF
B10: OTHER
B11: MEADS
B12: CIDER

Sheet Sheet3
A1: ESTRELLA_GALICIA | C1: CORE | D1: {=_xlfn.TEXTSPLIT(C1,";")} -> CORE | J1: CORE | K1: =VLOOKUP(J1,VARIANT!B:C,2,FALSE) -> CORE | S1: FRISDRANK | T1: =_xlfn.TEXTJOIN("','",TRUE,U1:BL1) -> FRISDRANK','JUICES','HOMEMADE','TEA','COFFEE','KOMBUCHA','CIDER','WHISKEY','JENEVER','WATER','MILKSHAKES','SMOOTHIES','PIZZAS','DFS','FRIES','SAUZEN','GIN','SALADS','SOUP','BITES','DIGESTIF','SHOTS','ICE_CREAM','SUPPLEMENTS','TEQUILA','SPIRITS','VODKA','SANDWICHES','DESSERT','BREAKFAST','PANCAKES','PASTAS','TOASTS','BURGERS','FOOD','REFRESHING','WINE','HOT_DRINKS','COCKTAILS','STRONG_DRINKS','APERITIF','OTHER','MEADS','BEER | U1: FRISDRANK | V1: JUICES | W1: HOMEMADE | X1: TEA | Y1: COFFEE | Z1: KOMBUCHA | AA1: CIDER | AB1: WHISKEY | AC1: JENEVER | AD1: WATER | AE1: MILKSHAKES | AF1: SMOOTHIES | AG1: PIZZAS | AH1: DFS | AI1: FRIES | AJ1: SAUZEN | AK1: GIN | AL1: SALADS | AM1: SOUP | AN1: BITES | AO1: DIGESTIF | AP1: SHOTS | AQ1: ICE_CREAM | AR1: SUPPLEMENTS | AS1: TEQUILA | AT1: SPIRITS | AU1: VODKA | AV1: SANDWICHES | AW1: DESSERT | AX1: BREAKFAST | AY1: PANCAKES | AZ1: PASTAS | BA1: TOASTS | BB1: BURGERS | BC1: FOOD | BD1: REFRESHING | BE1: WINE | BF1: HOT_DRINKS | BG1: COCKTAILS | BH1: STRONG_DRINKS | BI1: APERITIF | BJ1: OTHER | BK1: MEADS | BL1: BEER
A2: ANTIGOON | B2: =VLOOKUP(A2,BRAND!B:C,2,FALSE) -> ANTIGOON | C2: MILNUEVE | D2: {=_xlfn.TEXTSPLIT(C2,";")} -> MILNUEVE | J2: ACE | K2: =VLOOKUP(J2,VARIANT!B:C,2,FALSE) -> ACE | S2: JUICES
A3: ESTRELLA_GALICIA | B3: =VLOOKUP(A3,BRAND!B:C,2,FALSE) -> ESTRELLA_GALICIA;GALICA;GALICIA | C3: RED | D3: {=_xlfn.TEXTSPLIT(C3,";")} -> RED | J3: AMBER | K3: =VLOOKUP(J3,VARIANT!B:C,2,FALSE) -> AMBER;AMBREE;AMBRE | S3: HOMEMADE
A4: BEER_GEN | B4: =VLOOKUP(A4,BRAND!B:C,2,FALSE) -> IPA;HOUBLON;BEER;BIER;BIERE;PILSKE;PILS;PILSNER;CERVECA;BOERKE;FLUITJE;WITBIER | C4: BLACK | D4: {=_xlfn.TEXTSPLIT(C4,";")} -> BLACK | J4: APPLE | K4: =VLOOKUP(J4,VARIANT!B:C,2,FALSE) -> APPLE;APPEL;POMME;MANZANA;APFEL;POMMES | S4: TEA
A5: KATHEDRAAL | B5: =VLOOKUP(A5,BRAND!B:C,2,FALSE) -> KATHEDRAAL | C5: IRISH | D5: {=_xlfn.TEXTSPLIT(C5,";")} -> IRISH | J5: BITTER | K5: =VLOOKUP(J5,VARIANT!B:C,2,FALSE) -> BITTER | S5: COFFEE | U5: FRISDRANK','JUICES','HOMEMADE','TEA','COFFEE','KOMBUCHA','CIDER','WHISKEY','JENEVER','WATER','MILKSHAKES','SMOOTHIES','PIZZAS','DFS','FRIES','SAUZEN','GIN','SALADS','SOUP','BITES','DIGESTIF','SHOTS','ICE_CREAM','SUPPLEMENTS','TEQUILA','SPIRITS','VODKA','SANDWICHES','DESSERT','BREAKFAST','PANCAKES','PASTAS','TOASTS','BURGERS','FOOD','REFRESHING','WINE','HOT_DRINKS','COCKTAILS','STRONG_DRINKS','APERITIF','OTHER','MEADS','BEER
A6: MINUTE_MAID | B6: =VLOOKUP(A6,BRAND!B:C,2,FALSE) -> MAID;MINUTE_MADE;MINUTE_MATE;MINUTE_MAIT | C6: TRIPEL | D6: {=_xlfn.TEXTSPLIT(C6,";")} -> TRIPEL | J6: BLACK | K6: =VLOOKUP(J6,VARIANT!B:C,2,FALSE) -> BLACK;ZWARTE;ZWART;NOIR, | S6: KOMBUCHA
A7: POMTON_GEN | B7: =VLOOKUP(A7,BRAND!B:C,2,FALSE) -> POMTON;POM_TON | C7: XMAS | D7: {=_xlfn.TEXTSPLIT(C7,";")} -> XMAS | J7: BLUE | K7: =VLOOKUP(J7,VARIANT!B:C,2,FALSE) -> BLAUW;BLUE;BLEU;BLEUE;BLAUWE;BLAUW,;"BLUE";BLUE/ | S7: CIDER
A8: SCHUPPENBOER | B8: =VLOOKUP(A8,BRAND!B:C,2,FALSE) -> SCHUPPENBOER;SCHUPPEN_BOER | C8: AMBER | D8: {=_xlfn.TEXTSPLIT(C8,";")} -> AMBER | J8: BLOND | K8: =VLOOKUP(J8,VARIANT!B:C,2,FALSE) -> BLOND;BLONDE;BLONDA;BLONDE;BLOND/ | S8: WHISKEY
A9: SWAF_SILLY | B9: =VLOOKUP(A9,BRAND!B:C,2,FALSE) -> SILLY;SWAF | C9: IPA | D9: {=_xlfn.TEXTSPLIT(C9,";")} -> IPA | J9: BLOOD_ORANGE | K9: =VLOOKUP(J9,VARIANT!B:C,2,FALSE) -> BLOOD;BLOED;SANGINE;ARANCIATA_ROSSA | S9: JENEVER
A10: SUPER_BOCK | B10: =VLOOKUP(A10,BRAND!B:C,2,FALSE) -> SUPER_BOCK | C10: WHITE | D10: {=_xlfn.TEXTSPLIT(C10,";")} -> WHITE | J10: BROWN | K10: =VLOOKUP(J10,VARIANT!B:C,2,FALSE) -> BROWN;BRUNE;BRUIN;DONKERBRUIN;BRUIN0%;BRUINE;BRUN;BRUNETTE | S10: WATER
A11: TETE_DE_MORT | B11: =VLOOKUP(A11,BRAND!B:C,2,FALSE) -> TETE_DE_MORT;TE_DE_MORT | C11: PILSNER | D11: {=_xlfn.TEXTSPLIT(C11,";")} -> PILSNER | J11: CASSIS | K11: =VLOOKUP(J11,VARIANT!B:C,2,FALSE) -> CASSIS;GROSELLA_NEGRA;SCHWARZE_JOHANNISBEERE | S11: MILKSHAKES
A12: VIVEN | B12: =VLOOKUP(A12,BRAND!B:C,2,FALSE) -> VIVEN;NADA_IPA;BIRA_NADA | C12: HELLAS | D12: {=_xlfn.TEXTSPLIT(C12,";")} -> HELLAS | J12: CHERRY | K12: =VLOOKUP(J12,VARIANT!B:C,2,FALSE) -> CHERRY;KERS;CERISE;CEREZA;KIRSCHE;CHERRY;KRIEK;CERISE;CERISE,;KRIECK | S12: SMOOTHIES
A13: 1906 | B13: =VLOOKUP(A13,BRAND!B:C,2,FALSE) -> 1906 | C13: MOSCATEL | D13: {=_xlfn.TEXTSPLIT(C13,";")} -> MOSCATEL | J13: CHOCOLAT | K13: =VLOOKUP(J13,VARIANT!B:C,2,FALSE) -> CHOCOLAT | S13: PIZZAS
A14: 100_PAP | B14: =VLOOKUP(A14,BRAND!B:C,2,FALSE) -> 100_PAP | C14: CRAFT | D14: {=_xlfn.TEXTSPLIT(C14,";")} -> CRAFT | J14: XMAS | K14: =VLOOKUP(J14,VARIANT!B:C,2,FALSE) -> CHRISTMAS;XMAS;KERSTMIS;NOEL;CHRISMAS;KERST;NOAL | S14: DFS
A15: SHANDY_BEER_SPRITE | B15: =VLOOKUP(A15,BRAND!B:C,2,FALSE) -> SHANDY_BEER_SPRITE | C15: BLOND;AURORA | D15: {=_xlfn.TEXTSPLIT(C15,";")} -> BLOND | E15: AURORA | J15: CLASSIC | K15: =VLOOKUP(J15,VARIANT!B:C,2,FALSE) -> CLASSIC | S15: FRIES
A16: SAIGON | B16: =VLOOKUP(A16,BRAND!B:C,2,FALSE) -> SAIGON | C16: DARK;MEMENTO | D16: {=_xlfn.TEXTSPLIT(C16,";")} -> DARK | E16: MEMENTO | J16: COLA | K16: =VLOOKUP(J16,VARIANT!B:C,2,FALSE) -> COLA;KOLA | S16: SAUZEN
A17: NELLO_S | B17: =VLOOKUP(A17,BRAND!B:C,2,FALSE) -> NELLO_S | C17: GOLD | D17: {=_xlfn.TEXTSPLIT(C17,";")} -> GOLD | J17: CRANBERRY | K17: =VLOOKUP(J17,VARIANT!B:C,2,FALSE) -> CRANBERRY;VEENBES;CANNEBERGE;ARÃNDANO_ROJO;PREISELBEERE | S17: GIN
A18: AL_BLONDY | B18: =VLOOKUP(A18,BRAND!B:C,2,FALSE) -> AL_BLONDY | C18: PILNSER;CORE | D18: {=_xlfn.TEXTSPLIT(C18,";")} -> PILNSER | E18: CORE | J18: DARK | K18: =VLOOKUP(J18,VARIANT!B:C,2,FALSE) -> DONKERE;DARK;DONKER;NOIR | S18: SALADS
A19: MAMPOKO | B19: =VLOOKUP(A19,BRAND!B:C,2,FALSE) -> MAMPOKO | C19: RESERVA | D19: {=_xlfn.TEXTSPLIT(C19,";")} -> RESERVA | J19: GINGER | K19: =VLOOKUP(J19,VARIANT!B:C,2,FALSE) -> GINGER;GEMBER;GINGEMBRE;JENGIBRE;INGWER;GINGER | S19: SOUP
A20: EFES | B20: =VLOOKUP(A20,BRAND!B:C,2,FALSE) -> EFES | C20: GRAND | D20: {=_xlfn.TEXTSPLIT(C20,";")} -> GRAND | J20: GINGER_ALE | K20: =VLOOKUP(J20,VARIANT!B:C,2,FALSE) -> GINGER_ALE | S20: BITES
A21: FIX | B21: =VLOOKUP(A21,BRAND!B:C,2,FALSE) -> FIX | C21: LAGER | D21: {=_xlfn.TEXTSPLIT(C21,";")} -> LAGER | J21: GINGER_BEER | K21: =VLOOKUP(J21,VARIANT!B:C,2,FALSE) -> GINGER_BEER | S21: DIGESTIF
A22: TORNADO | B22: =VLOOKUP(A22,BRAND!B:C,2,FALSE) -> TORNADO | C22: WHEAT | D22: {=_xlfn.TEXTSPLIT(C22,";")} -> WHEAT | J22: GOLD | K22: =VLOOKUP(J22,VARIANT!B:C,2,FALSE) -> GOUD;DORE;DORE;GOLD;DOREE;DOREE;DORE;D_OR | S22: SHOTS
A23: BELMONDO | B23: =VLOOKUP(A23,BRAND!B:C,2,FALSE) -> BELMONDO | C23: BLOND;YUZU;CORE | D23: {=_xlfn.TEXTSPLIT(C23,";")} -> BLOND | E23: YUZU | F23: CORE | J23: GRAPEFRUIT | K23: =VLOOKUP(J23,VARIANT!B:C,2,FALSE) -> GRAPEFRUIT;PAMPLEMOUSSE,;PAMPLEMOUSSE;POMPELMOES;PAMPLEMOUS | S23: ICE_CREAM
A24: PRESIDENTE | B24: =VLOOKUP(A24,BRAND!B:C,2,FALSE) -> PRESIDENTE | C24: IPA;CORE | D24: {=_xlfn.TEXTSPLIT(C24,";")} -> IPA | E24: CORE | J24: GREEN | K24: =VLOOKUP(J24,VARIANT!B:C,2,FALSE) -> GREEN;GROEN;VERT;VERDE;;GROEN;VERT;GREEN;GREEN,;VERTE | S24: SUPPLEMENTS
A25: POLAR | B25: =VLOOKUP(A25,BRAND!B:C,2,FALSE) -> POLAR | C25: DIPA;CORE | D25: {=_xlfn.TEXTSPLIT(C25,";")} -> DIPA | E25: CORE | J25: PINK | K25: =VLOOKUP(J25,VARIANT!B:C,2,FALSE) -> H_PINK;PINK;ROZE | S25: TEQUILA
A26: EXCELSIOR | B26: =VLOOKUP(A26,BRAND!B:C,2,FALSE) -> EXCELSIOR | C26: CORE;KRIEK | D26: {=_xlfn.TEXTSPLIT(C26,";")} -> CORE | E26: KRIEK | J26: IPA | K26: =VLOOKUP(J26,VARIANT!B:C,2,FALSE) -> IPA;INDIA_PALE_ALE;I.P.A;I.P.A. | S26: SPIRITS
A27: CLASH_OF_THE_TITANS | B27: =VLOOKUP(A27,BRAND!B:C,2,FALSE) -> CLASH_OF_THE_TITANS | C27: SARDEGNA | D27: {=_xlfn.TEXTSPLIT(C27,";")} -> SARDEGNA | J27: LAGER | K27: =VLOOKUP(J27,VARIANT!B:C,2,FALSE) -> LAGER;FLUITJE;BOERKE | S27: VODKA
A28: SCANNING_FOR_SIGNS | B28: =VLOOKUP(A28,BRAND!B:C,2,FALSE) -> SCANNING_FOR_SIGNS | C28: RED;BROWN | D28: {=_xlfn.TEXTSPLIT(C28,";")} -> RED | E28: BROWN | J28: LEMON | K28: =VLOOKUP(J28,VARIANT!B:C,2,FALSE) -> LEMON;CITROEN;CITRON;LIMÃ“N;ZITRONE;LIMONATA;CITROEN/;CITRON,;LIMOEN,;LIMONE;LEMON, | S28: SANDWICHES
A29: STAR | B29: =VLOOKUP(A29,BRAND!B:C,2,FALSE) -> STAR | D29: {=_xlfn.TEXTSPLIT(C29,";")} -> #VALUE! | J29: LIME | K29: =VLOOKUP(J29,VARIANT!B:C,2,FALSE) -> LIME;LIMOEN;CITRON_VERT;LIMA;LIMETTE | S29: DESSERT
A30: UIJIN | B30: =VLOOKUP(A30,BRAND!B:C,2,FALSE) -> UIJIN | C30: EVIL | D30: {=_xlfn.TEXTSPLIT(C30,";")} -> EVIL | J30: LYCHEE | K30: =VLOOKUP(J30,VARIANT!B:C,2,FALSE) -> LYCHEE;LYCHEE;LITCHI;LICHI;LITSCHI | S30: BREAKFAST
A31: OWA | B31: =VLOOKUP(A31,BRAND!B:C,2,FALSE) -> OWA | C31: CLASSIC;CORE | D31: {=_xlfn.TEXTSPLIT(C31,";")} -> CLASSIC | E31: CORE | J31: MANGO | K31: =VLOOKUP(J31,VARIANT!B:C,2,FALSE) -> MANGO;MANGO;MANGUE;MANGO;MANGO | S31: PANCAKES
A32: BITTERE_BLOEMEN | B32: =VLOOKUP(A32,BRAND!B:C,2,FALSE) -> BITTERE_BLOEMEN | C32: STOUT | D32: {=_xlfn.TEXTSPLIT(C32,";")} -> STOUT | J32: MINT | K32: =VLOOKUP(J32,VARIANT!B:C,2,FALSE) -> MINT;MUNT;MENTHE;MENTA;MINZE;MUNT, | S32: PASTAS
A33: JOUR_DE_FETE | B33: =VLOOKUP(A33,BRAND!B:C,2,FALSE) -> JOUR_DE_FETE | C33: ABADIA | D33: {=_xlfn.TEXTSPLIT(C33,";")} -> ABADIA | J33: MOJITO | K33: =VLOOKUP(J33,VARIANT!B:C,2,FALSE) -> MOJITO | S33: TOASTS
A34: THE_BELGIAN_CIDER | B34: =VLOOKUP(A34,BRAND!B:C,2,FALSE) -> THE_BELGIAN_CIDER | C34: RADLER;GREEN;LEMON | D34: {=_xlfn.TEXTSPLIT(C34,";")} -> RADLER | E34: GREEN | F34: LEMON | J34: MULTIFRUIT | K34: =VLOOKUP(J34,VARIANT!B:C,2,FALSE) -> MULTIFRUIT;MULTIVRUCHT;MULTIFRUITS;MULTIFRUTA;MEHRFRUCHT;MULTIVRUCHTEN;VRUCHTENKORF;FRUITKORF | S34: BURGERS
A35: DOKKIE | B35: =VLOOKUP(A35,BRAND!B:C,2,FALSE) -> DOKKIE | C35: SKY | D35: {=_xlfn.TEXTSPLIT(C35,";")} -> SKY | J35: MULTIVITAMIN | K35: =VLOOKUP(J35,VARIANT!B:C,2,FALSE) -> MULTIVITAMIN;MULTI_VITAMIN | S35: FOOD
A36: PERLE | B36: =VLOOKUP(A36,BRAND!B:C,2,FALSE) -> PERLE | C36: TANGO | D36: {=_xlfn.TEXTSPLIT(C36,";")} -> TANGO | J36: ORIGINAL | K36: =VLOOKUP(J36,VARIANT!B:C,2,FALSE) -> ORIGINAL | S36: REFRESHING
A37: IFIGENIA | B37: =VLOOKUP(A37,BRAND!B:C,2,FALSE) -> IFIGENIA | C37: MALT;CORE | D37: {=_xlfn.TEXTSPLIT(C37,";")} -> MALT | E37: CORE | J37: PASSION | K37: =VLOOKUP(J37,VARIANT!B:C,2,FALSE) -> PASSION | S37: WINE
A38: LES_PERLES_DU_HOMARD | B38: =VLOOKUP(A38,BRAND!B:C,2,FALSE) -> LES_PERLES_DU_HOMARD | C38: ORIGINAL;CORE | D38: {=_xlfn.TEXTSPLIT(C38,";")} -> ORIGINAL | E38: CORE | J38: PEACH | K38: =VLOOKUP(J38,VARIANT!B:C,2,FALSE) -> PEACH;PERZIK;PÃŠCHE;MELOCOT;PFIRSICH;PCHERESSE;Píche;PEACH;PERZIK;PCHE;PICHE,;PECHE;PICHERESSE | S38: HOT_DRINKS
A39: OCATA | B39: =VLOOKUP(A39,BRAND!B:C,2,FALSE) -> OCATA | C39: ORANGE | D39: {=_xlfn.TEXTSPLIT(C39,";")} -> ORANGE | J39: PILSNER | K39: =VLOOKUP(J39,VARIANT!B:C,2,FALSE) -> PILS;PINTJE;BIRA;FLUIT;BOERKE;PINKE | S39: COCKTAILS
A40: WARMOUTH | B40: =VLOOKUP(A40,BRAND!B:C,2,FALSE) -> WARMOUTH | C40: APPLE | D40: {=_xlfn.TEXTSPLIT(C40,";")} -> APPLE | J40: PINEAPPLE | K40: =VLOOKUP(J40,VARIANT!B:C,2,FALSE) -> PINEAPPLE;ANANAS;ANANAS, | S40: STRONG_DRINKS
...

Sheet Sheet4
A1: 13 | PILSNER | | B1: 13 | C1: PILSNER | E1: 13 | F1: PILSNER
A2: 1818 | SAISON | | B2: 1818 | C2: SAISON | E2: 1818 | F2: SAISON
A3: 3_FONTEINEN | CUVEE_ARMAND_GASTON | | B3: 3_FONTEINEN | C3: CUVEE_ARMAND_GASTON | E3: 3_FONTEINEN | F3: CUVEE_ARMAND_GASTON
A4: 3_FONTEINEN | RED | | B4: 3_FONTEINEN | C4: RED | E4: 3_FONTEINEN | F4: RED
A5: 3_MONTS | AMBREE | | B5: 3_MONTS | C5: AMBREE | E5: 3_MONTS | F5: AMBREE
A6: 8_6 | CORE | | B6: 8_6 | C6: CORE | E6: 8_6 | F6: CORE
A8: AIRBORNE | BLOND | | B8: AIRBORNE | C8: BLOND | E8: AIRBORNE | F8: BLOND
A9: AMSTEL | BLOND | | B9: AMSTEL | C9: BLOND | E9: AMSTEL | F9: BLOND
A10: AMSTEL | PILSNER | ZERO | B10: AMSTEL | C10: PILSNER | D10: ZERO | E10: AMSTEL | F10: PILSNER | G10: ZERO
A11: AMSTEL | LEMON | | B11: AMSTEL | C11: LEMON | E11: AMSTEL | F11: LEMON
A12: AMSTEL | BOCK | | B12: AMSTEL | C12: BOCK | E12: AMSTEL | F12: BOCK
A13: AMSTEL | ROSE | | B13: AMSTEL | C13: ROSE | E13: AMSTEL | F13: ROSE
A14: ARDENNE | SAISON | | B14: ARDENNE | C14: SAISON | E14: ARDENNE | F14: SAISON
A15: BAPTIST | FARMHOUSE_ALE | SAISON | | B15: BAPTIST | C15: FARMHOUSE_ALE | D15: SAISON | | E15: BAPTIST | F15: FARMHOUSE_ALE | G15: SAISON |
A16: BARBE | DUBBEL | | B16: BARBE | C16: DUBBEL | E16: BARBE | F16: DUBBEL
A17: BARBE | XMAS | | B17: BARBE | C17: XMAS | E17: BARBE | F17: XMAS
A18: BAVIK | WHITE | | B18: BAVIK | C18: WHITE | E18: BAVIK | F18: WHITE
A19: BEER_GEN | ALTBIER > TRADITIONAL| ZERO | B19: BEER_GEN | C19: ALTBIER > TRADITIONAL| ZERO | E19: BEER_GEN | F19: ALTBIER > TRADITIONAL| ZERO
A20: BEER_GEN | BARLEYWINE > AMERICAN| ZERO | B20: BEER_GEN | C20: BARLEYWINE > AMERICAN| ZERO | E20: BEER_GEN | F20: BARLEYWINE > AMERICAN| ZERO
A21: BEER_GEN | BELGIAN_TRIPEL| ZERO | B21: BEER_GEN | C21: BELGIAN_TRIPEL| ZERO | E21: BEER_GEN | F21: BELGIAN_TRIPEL| ZERO
A22: BEER_GEN | FARO_LAMBIC | ZERO | B22: BEER_GEN | C22: FARO_LAMBIC | D22: ZERO | E22: BEER_GEN | F22: FARO_LAMBIC | G22: ZERO
A23: BEER_GEN | OUD_BRUIN | ZERO | B23: BEER_GEN | C23: OUD_BRUIN | D23: ZERO | E23: BEER_GEN | F23: OUD_BRUIN | G23: ZERO
A24: BEER_GEN | OUDE_GUEUZE | ZERO | B24: BEER_GEN | C24: OUDE_GUEUZE | D24: ZERO | E24: BEER_GEN | F24: OUDE_GUEUZE | G24: ZERO
A25: BEER_GEN | SAISON;BEER_GEN | BLOOD_ORANGE | | ZERO | B25: #VALUE! | E25: #VALUE!
A26: BEER_GEN | SPIRIT_FLAVOURED_BEERS | ZERO | B26: BEER_GEN | C26: SPIRIT_FLAVOURED_BEERS | D26: ZERO | E26: BEER_GEN | F26: SPIRIT_FLAVOURED_BEERS | G26: ZERO
A27: BELGIAN | 8 | | B27: BELGIAN | C27: 8 | E27: BELGIAN | F27: 8
A28: BESTIALE | BLOND | LIGHT | B28: BESTIALE | C28: BLOND | D28: LIGHT | E28: BESTIALE | F28: BLOND | G28: LIGHT
A29: BINCHOISE | XMAS | | B29: BINCHOISE | C29: XMAS | E29: BINCHOISE | F29: XMAS
A30: BLAUW | BLUE | | B30: BLAUW | C30: BLUE | E30: BLAUW | F30: BLUE
A31: BLOEMEKEI | TRIPEL | | B31: BLOEMEKEI | C31: TRIPEL | E31: BLOEMEKEI | F31: TRIPEL
A32: BOGAERDENL | TRIPEL | | B32: BOGAERDENL | C32: TRIPEL | E32: BOGAERDENL | F32: TRIPEL
A33: BOUDELO | BLOND | | B33: BOUDELO | C33: BLOND | E33: BOUDELO | F33: BLOND
A34: BRAND | PILSNER | | B34: BRAND | C34: PILSNER | E34: BRAND | F34: PILSNER
A35: BROGNE | TRIPEL | | B35: BROGNE | C35: TRIPEL | E35: BROGNE | F35: TRIPEL
A36: BROGNE | XMAS | | B36: BROGNE | C36: XMAS | E36: BROGNE | F36: XMAS
A37: BROUWERIJ__T_IJ | CORE | | B37: BROUWERIJ__T_IJ | C37: CORE | E37: BROUWERIJ__T_IJ | F37: CORE
A38: BROUWERIJ_T_IJ | SESSION | | B38: BROUWERIJ_T_IJ | C38: SESSION | E38: BROUWERIJ_T_IJ | F38: SESSION
A39: BUFFALO_BITTER | BITTER | | B39: BUFFALO_BITTER | C39: BITTER | E39: BUFFALO_BITTER | F39: BITTER
A40: BUSH | AMBER | | B40: BUSH | C40: AMBER | E40: BUSH | F40: AMBER
... A50: CAULIER | IPA | | B50: CAULIER | C50: IPA | E50: CAULIER | F50: IPA
...

Sheet Sheet5
A1: BEER_GEN | B1: BEER_GEN | G1: ALTBIER > STICKE | H1: {=_xlfn.TEXTSPLIT(G1,";")} -> ALTBIER > STICKE | M1: ALTBIER > STICKE
A2: VLETEREN | B2: VLETEREN | G2: ALTBIER > TRADITIONAL | H2: {=_xlfn.TEXTSPLIT(G2,";")} -> ALTBIER > TRADITIONAL | M2: ALTBIER > TRADITIONAL | O2: CORE
A3: CLASH_OF_THE_TITANS | B3: CLASH_OF_THE_TITANS | G3: ALTBIER > TRADITIONAL| ZERO | H3: {=_xlfn.TEXTSPLIT(G3,";")} -> ALTBIER > TRADITIONAL| ZERO | M3: ALTBIER > TRADITIONAL| ZERO | O3: 10
A4: SHANDY_BEER_SPRITE | B4: SHANDY_BEER_SPRITE | G4: CORE | H4: {=_xlfn.TEXTSPLIT(G4,";")} -> CORE | M4: CORE | O4: HOP
A5: SPAVELA | B5: SPAVELA | G5: AUSTRALIAN_SPARKLING_ALE | H5: {=_xlfn.TEXTSPLIT(G5,";")} -> AUSTRALIAN_SPARKLING_ALE | M5: AUSTRALIAN_SPARKLING_ALE | O5: BROWN
A6: TANGO | B6: TANGO | G6: GRAND | H6: {=_xlfn.TEXTSPLIT(G6,";")} -> GRAND | M6: GRAND | O6: BOVENGRONDS
A7: ATRIUM | B7: ATRIUM | G7: RESERVA | H7: {=_xlfn.TEXTSPLIT(G7,";")} -> RESERVA | M7: RESERVA | O7: 4
A8: AVOUERIE_D_ANTI | B8: AVOUERIE_D_ANTI | G8: BARLEYWINE > AMERICAN | H8: {=_xlfn.TEXTSPLIT(G8,";")} -> BARLEYWINE > AMERICAN | M8: BARLEYWINE > AMERICAN | O8: BLOND
A9: BATTELIEK | B9: BATTELIEK | G9: BARLEYWINE > AMERICAN| ZERO | H9: {=_xlfn.TEXTSPLIT(G9,";")} -> BARLEYWINE > AMERICAN| ZERO | M9: BARLEYWINE > AMERICAN| ZERO | O9: LUX
A10: BEERSTORMING | B10: BEERSTORMING | G10: BARLEYWINE > ENGLISH | H10: {=_xlfn.TEXTSPLIT(G10,";")} -> BARLEYWINE > ENGLISH | M10: BARLEYWINE > ENGLISH | O10: DUBBEL
A11: CANNAHOPPER | B11: CANNAHOPPER | G11: BARLEYWINE > OTHER | H11: {=_xlfn.TEXTSPLIT(G11,";")} -> BARLEYWINE > OTHER | M11: BARLEYWINE > OTHER
A12: CHTI | B12: CHTI | G12: BEER_SODA_MIX | H12: {=_xlfn.TEXTSPLIT(G12,";")} -> BEER_SODA_MIX | M12: BEER_SODA_MIX | O12: DARK
A13: CURCU | B13: CURCU | G13: CORE;GRENADINE | H13: {=_xlfn.TEXTSPLIT(G13,";")} -> CORE | I13: GRENADINE | M13: INFUSED | O13: NOX
A14: DAME_JEANNE | B14: DAME_JEANNE | G14: INFUSED | H14: {=_xlfn.TEXTSPLIT(G14,";")} -> INFUSED | M14: BAOBAB | O14: PATERSBIER
A15: DODOENS | B15: DODOENS | G15: BAOBAB | H15: {=_xlfn.TEXTSPLIT(G15,";")} -> BAOBAB | M15: BEERS_OTHER | O15: BLUE
A16: FREE_BREW | B16: FREE_BREW | G16: BEERS_OTHER;CORE | H16: {=_xlfn.TEXTSPLIT(G16,";")} -> BEERS_OTHER | I16: CORE | M16: PINK | O16: QUADRUPEL
A17: GLEZIA | B17: GLEZIA | G17: PINK | H17: {=_xlfn.TEXTSPLIT(G17,";")} -> PINK | M17: GARDE | O17: RED
A18: GRANDGOUSIER | B18: GRANDGOUSIER | G18: GARDE | H18: {=_xlfn.TEXTSPLIT(G18,";")} -> GARDE | M18: GINGER | O18: GREEN
A19: HOF_TEN_DORMAAL | B19: HOF_TEN_DORMAAL | G19: GINGER | H19: {=_xlfn.TEXTSPLIT(G19,";")} -> GINGER | M19: DAD | O19: GOLD
A20: KOT_MADAM | B20: KOT_MADAM | G20: DAD | H20: {=_xlfn.TEXTSPLIT(G20,";")} -> DAD | M20: WINTER | O20: TRIPEL
A21: L_ADOREE | B21: L_ADOREE | G21: WINTER | H21: {=_xlfn.TEXTSPLIT(G21,";")} -> WINTER | M21: TRIPEL | O21: CHAMPAGNE
A22: LA_BELLE_DES_VIGNES | B22: LA_BELLE_DES_VIGNES | G22: TRIPEL | H22: {=_xlfn.TEXTSPLIT(G22,";")} -> TRIPEL | M22: STOUT | O22: MAIBOCK
A23: LA_CHINETTE | B23: LA_CHINETTE | G23: STOUT | H23: {=_xlfn.TEXTSPLIT(G23,";")} -> STOUT | M23: GUEUZE | O23: COLA
A24: LA_CLE_DU_BONHEUR | B24: LA_CLE_DU_BONHEUR | G24: GUEUZE | H24: {=_xlfn.TEXTSPLIT(G24,";")} -> GUEUZE | M24: BEERS_SPECIAL | O24: FRUIT
A25: LA_ROY_D_ESPAGNE | B25: LA_ROY_D_ESPAGNE | G25: BEERS_SPECIAL | H25: {=_xlfn.TEXTSPLIT(G25,";")} -> BEERS_SPECIAL | M25: CRAFT | O25: RUBY
A26: LA_WATERLOOTOISE | B26: LA_WATERLOOTOISE | G26: CRAFT;CORE | H26: {=_xlfn.TEXTSPLIT(G26,";")} -> CRAFT | I26: CORE | M26: BLOND | O26: CHERRY
A27: LUVANIUM | B27: LUVANIUM | G27: BLOND;CORE | H27: {=_xlfn.TEXTSPLIT(G27,";")} -> BLOND | I27: CORE | M27: SUMMER | O27: BERRY
A28: MAREDRET | B28: MAREDRET | G28: SUMMER | H28: {=_xlfn.TEXTSPLIT(G28,";")} -> SUMMER | M28: VISTA | O28: LIME
A29: SUPERMALT | B29: SUPERMALT | G29: VISTA | H29: {=_xlfn.TEXTSPLIT(G29,";")} -> VISTA | M29: HOP | O29: ORIGINAL
A30: TIMMERMANS | B30: TIMMERMANS | G30: HOP;CORE | H30: {=_xlfn.TEXTSPLIT(G30,";")} -> HOP | I30: CORE | M30: NATURE | O30: POMEGRANATE
A31: TORNADO | B31: TORNADO | G31: NATURE | H31: {=_xlfn.TEXTSPLIT(G31,";")} -> NATURE | M31: PRIOR | O31: PILSNER
A32: UNWRAPP | B32: UNWRAPP | G32: PRIOR | H32: {=_xlfn.TEXTSPLIT(G32,";")} -> PRIOR | M32: DUBBEL | O32: GINSENG
A33: VERY_CHIC | B33: VERY_CHIC | G33: BLOND | H33: {=_xlfn.TEXTSPLIT(G33,";")} -> BLOND | M33: SINGLE | O33: BITTER
A34: VICARIS | B34: VICARIS | G34: BLOND;YUZU;CORE | H34: {=_xlfn.TEXTSPLIT(G34,";")} -> BLOND | I34: YUZU | J34: CORE | M34: DARK | O34: GINGER
A35: ABATTOIR_VIANE | B35: ABATTOIR_VIANE | G35: DUBBEL | H35: {=_xlfn.TEXTSPLIT(G35,";")} -> DUBBEL | M35: QUADRUPEL | O35: TROPICAL
A36: BELMONDO | B36: BELMONDO | G36: SINGLE | H36: {=_xlfn.TEXTSPLIT(G36,";")} -> SINGLE | M36: GALLANT | O36: AMBER
A37: CERCUEIL | B37: CERCUEIL | G37: DARK | H37: {=_xlfn.TEXTSPLIT(G37,";")} -> DARK | O37: SODA
A38: CLAUDETTE | B38: CLAUDETTE | G38: QUADRUPEL | H38: {=_xlfn.TEXTSPLIT(G38,";")} -> QUADRUPEL | M38: WIJZE | O38: STILL
A39: DE_KOM | B39: DE_KOM | G39: DARK;MEMENTO | H39: {=_xlfn.TEXTSPLIT(G39,";")} -> DARK | I39: MEMENTO | M39: AMBER | O39: LEMON
A40: DE_LOGT | B40: DE_LOGT | G40: GALLANT;GRAND_CRU | H40: {=_xlfn.TEXTSPLIT(G40,";")} -> GALLANT | I40: GRAND_CRU | M40: CANTOR | O40: BITTER_LEMON
...
